Workbook
Name D: Task_hours!$D$112

Sheet Stories
A1: Story | B1: Title | C1: Note | D1: Priority | E1: Risk | F1: Estimate | G1: Actual | H1: Iteration | I1: Status
A2: 1 | B2: GESTION DES COMPTES UTILISATEURS | D2: 1 | E2: 1 | F2: 23 | G2: 35.5 | H2: 1 | I2: Done | K2: Iteration | L2: Estimate | M2: Refactor | N2: Total
A3: 2 | B3: GESTION DES PAQUETS DE CARTES | D3: 1 | E3: 2 | F3: 48.5 | G3: 43 | H3: 2 | I3: Done | K3: 1 | L3: =SUMIF($H$2:$H$23,$K3,$F$2:$F$23) -> 38 | M3: 0 | N3: =L3+M3 -> 38
A4: 3 | B4: CREATION DE CARTES DANS UN PAQUET | D4: 1 | E4: 1 | F4: 15 | G4: 17 | H4: 1 | I4: Done | K4: 2 | L4: =SUMIF($H$2:$H$23,$K4,$F$2:$F$23) -> 88.5 | M4: 18 | N4: =L4+M4 -> 106.5
A5: 4 | B5: ETUDIER UN JEU DE CARTES | D5: 1 | E5: 2 | F5: 13 | G5: 8 | H5: 2 | I5: Done | K5: 3 | L5: =SUMIF($H$2:$H$23,$K5,$F$2:$F$23) -> 105 | M5: 15 | N5: =L5+M5 -> 120
A6: 5 | B6: METHODE DE TIRAGE | C6: Done in Story 6 ? | D6: 2 | I6: Done | K6: 4 | L6: =SUMIF($H$2:$H$23,$K6,$F$2:$F$23) -> 102 | M6: 30 | N6: =L6+M6 -> 132
A7: 6 | B7: MODES DE JEU | D7: 2 | E7: 2 | F7: 27 | G7: 21 | H7: 2 | I7: Done
A8: 7 | B8: QUESTIONS DE DIFFERENTS TYPES | D8: 3 | I8: Skip | K8: Iteration | L8: Actual | M8: Refactor | N8: Total
A9: 8 | B9: REPONSES DE DIFFERENTS TYPES | D9: 2 | E9: 1 | F9: 35 | G9: 16 | H9: 4 | I9: Done | K9: 1 | L9: =SUMIF($H$2:$H$23,$K9,$G$2:$G$23) -> 52.5 | M9: 0 | N9: =L9+M9 -> 52.5
A10: 9 | B10: STATISTIQUES D’ENTRAINEMENT | D10: 3 | E10: 3 | F10: 30 | G10: 37 | H10: 4 | I10: Done | K10: 2 | L10: =SUMIF($H$2:$H$23,$K10,$G$2:$G$23) -> 72 | M10: 16.5 | N10: =L10+M10 -> 88.5
A11: 10 | B11: CONNEXION A UN SERVEUR | C11: Use a BaaS or DB in cloud | D11: 2 | E11: 1 | F11: 50 | G11: 43 | H11: 3 | I11: Done | K11: 3 | L11: =SUMIF($H$2:$H$23,$K11,$G$2:$G$23) -> 81 | M11: 26 | N11: =L11+M11 -> 107
A12: 11 | B12: STORE DE JEUX DE CARTES | D12: 3 | E12: 3 | F12: 25 | G12: 18.5 | H12: 4 | I12: Done | K12: 4 | L12: =SUMIF($H$2:$H$23,$K12,$G$2:$G$23) -> 74.5 | M12: 63 | N12: =L12+M12 -> 137.5
A13: 12 | B13: SCORE ET CLASSEMENT | D13: 3 | I13: Skip
A14: 13 | B14: VERSION MOBILE | C14: To hard to complete in time | D14: 3 | I14: Skip
A15: 14 | B15: LECTURE AUDIO | D15: 3 | E15: 3 | F15: 12 | G15: 3 | H15: 4 | I15: Done
A16: 15 | B16: IMPORT/EXPORT DE JEUX DE CARTES | D16: 2 | E16: 2 | F16: 10 | G16: 8.5 | H16: 3 | I16: Done
A17: 16 | B17: IMPRESSION DE JEUX DE CARTES | D17: 2 | E17: 2 | F17: 15 | G17: 7 | H17: 3 | I17: Done
A18: 17 | B18: LATEX ET HTML DANS LES CARTES | D18: 1 | E18: 1 | F18: 30 | G18: 22.5 | H18: 3 | I18: Done
A19: 18 | B19: SUCCES | D19: 3 | I19: Skip
A20: 19 | B20: NOTIFICATIONS DE REVISION | D20: 3 | I20: Skip
A21: 20 | B21: CARTES A CHOIX DE DIFFICULTE | D21: 2 | I21: Skip
A22: 21 | B22: CARTES MODULABLES | D22: 3 | I22: Skip
A23: 22 | B23: DUEL | D23: 3 | I23: Skip

Sheet Task_hours
A1: Please enter your tasks hours here each time your work on a story task. There can be multiple entries for the same date and/or the same task. They will be then summed automatically in other sheets. Please refer - the task ID (see Tasks sheet); the Story and the Title are updated automatically - the current Iteration - the Date you worked on - the Pilote and the Co-pilote - the number of Hours worked These real hours are reflected automatically in Calendar and in Tasks. Calendar should not be modified. Tasks should only be modified when adding a new task or modifying an existing one.
A3: ID | B3: Iteration | C3: Story | D3: Title | E3: Date | F3: Pilote | G3: Co-Pilote | H3: Hours
A4: C2-3 | B4: =IFERROR(VLOOKUP(A4, Tasks!A$42:E$133,2, FALSE), "") -> 2 | C4: =IFERROR(VLOOKUP(A4, Tasks!A$42:E$133,3, FALSE), "") -> C2 | D4: =IFERROR(VLOOKUP(A4, Tasks!A$42:E$133,5, FALSE), "") -> EditDeck (FXML): Create deck list table | E4: 45001 | F4: Antoine | G4: Elliot | H4: 1
A5: C2-14 | B5: =IFERROR(VLOOKUP(A5, Tasks!A$42:E$133,2, FALSE), "") -> 2 | C5: =IFERROR(VLOOKUP(A5, Tasks!A$42:E$133,3, FALSE), "") -> C2 | D5: =IFERROR(VLOOKUP(A5, Tasks!A$42:E$133,5, FALSE), "") -> DeckList (ProfileController): Pass deck ID from profile view to deckEdit view when pushing edit btn | E5: 45001 | F5: Elliot | G5: Antoine | H5: 1
A6: D3-1 | B6: =IFERROR(VLOOKUP(A6, Tasks!A$42:E$133,2, FALSE), "") -> 2 | C6: =IFERROR(VLOOKUP(A6, Tasks!A$42:E$133,3, FALSE), "") -> D3 | D6: =IFERROR(VLOOKUP(A6, Tasks!A$42:E$133,5, FALSE), "") -> Tracking: task excel on google sheets | E6: 45001 | F6: Antoine | G6: Luca | H6: 1
A7: D3-2 | B7: =IFERROR(VLOOKUP(A7, Tasks!A$42:E$133,2, FALSE), "") -> 2 | C7: =IFERROR(VLOOKUP(A7, Tasks!A$42:E$133,3, FALSE), "") -> D3 | D7: =IFERROR(VLOOKUP(A7, Tasks!A$42:E$133,5, FALSE), "") -> Tracking: Burndown Chart | E7: 45001 | F7: Luca | G7: Antoine | H7: 1
A8: D2-3 | B8: 2 | C8: =IFERROR(VLOOKUP(A8, Tasks!A$42:E$133,3, FALSE), "") -> D2 | D8: =IFERROR(VLOOKUP(A8, Tasks!A$42:E$133,5, FALSE), "") -> Refactor: Fix layout for the SignIn & SignUp view | E8: 45002 | F8: Francesco | G8: Dave | H8: 1
A9: D2-1 | B9: =IFERROR(VLOOKUP(A9, Tasks!A$42:E$133,2, FALSE), "") -> 2 | C9: =IFERROR(VLOOKUP(A9, Tasks!A$42:E$133,3, FALSE), "") -> D2 | D9: =IFERROR(VLOOKUP(A9, Tasks!A$42:E$133,5, FALSE), "") -> Refactor: Split the SignIn & SignUp controller | E9: 45002 | F9: Francesco | G9: Dave | H9: 1
A10: D2-2 | B10: =IFERROR(VLOOKUP(A10, Tasks!A$42:E$133,2, FALSE), "") -> 2 | C10: =IFERROR(VLOOKUP(A10, Tasks!A$42:E$133,3, FALSE), "") -> D2 | D10: =IFERROR(VLOOKUP(A10, Tasks!A$42:E$133,5, FALSE), "") -> Refactor: Split the Profile & Settings Controller | E10: 45002 | F10: Elliot | G10: Antoine | H10: 1
A11: D2-2 | B11: 2 | C11: =IFERROR(VLOOKUP(A11, Tasks!A$42:E$133,3, FALSE), "") -> D2 | D11: =IFERROR(VLOOKUP(A11, Tasks!A$42:E$133,5, FALSE), "") -> Refactor: Split the Profile & Settings Controller | E11: 45002 | F11: Luca | G11: Ismael | H11: 1
A12: D4-1 | B12: =IFERROR(VLOOKUP(A12, Tasks!A$42:E$133,2, FALSE), "") -> 2 | C12: =IFERROR(VLOOKUP(A12, Tasks!A$42:E$133,3, FALSE), "") -> D4 | D12: =IFERROR(VLOOKUP(A12, Tasks!A$42:E$133,5, FALSE), "") -> Docs: refaire le README.md | E12: 45002 | F12: Francesco | G12: Dave | H12: 0.5
A13: C4-1 | B13: 2 | C13: =IFERROR(VLOOKUP(A13, Tasks!A$42:E$133,3, FALSE), "") -> C4 | D13: =IFERROR(VLOOKUP(A13, Tasks!A$42:E$133,5, FALSE), "") -> Study: Refactor the editDeck view into the static Study view (FlashCard view) | E13: 45004 | F13: Luca | G13: Emile | H13: 2
A14: C2-2 | B14: =IFERROR(VLOOKUP(A14, Tasks!A$42:E$133,2, FALSE), "") -> 2 | C14: =IFERROR(VLOOKUP(A14, Tasks!A$42:E$133,3, FALSE), "") -> C2 | D14: =IFERROR(VLOOKUP(A14, Tasks!A$42:E$133,5, FALSE), "") -> EditDeck (FXML): Create global title and edit buttons | E14: 45004 | F14: Antoine | G14: Elliot | H14: 1.5
A15: C2-3 | B15: =IFERROR(VLOOKUP(A15, Tasks!A$42:E$133,2, FALSE), "") -> 2 | C15: =IFERROR(VLOOKUP(A15, Tasks!A$42:E$133,3, FALSE), "") -> C2 | D15: =IFERROR(VLOOKUP(A15, Tasks!A$42:E$133,5, FALSE), "") -> EditDeck (FXML): Create deck list table | E15: 45004 | F15: Antoine | G15: Elliot | H15: 1.5
A16: C2-4 | B16: =IFERROR(VLOOKUP(A16, Tasks!A$42:E$133,2, FALSE), "") -> 2 | C16: =IFERROR(VLOOKUP(A16, Tasks!A$42:E$133,3, FALSE), "") -> C2 | D16: =IFERROR(VLOOKUP(A16, Tasks!A$42:E$133,5, FALSE), "") -> EditDeck (DeckEditController): Load fake deck cards dynamically in list | E16: 45004 | F16: Antoine | G16: Elliot | H16: 0.5
A17: C4-1 | B17: =IFERROR(VLOOKUP(A17, Tasks!A$42:E$133,2, FALSE), "") -> 2 | C17: =IFERROR(VLOOKUP(A17, Tasks!A$42:E$133,3, FALSE), "") -> C4 | D17: =IFERROR(VLOOKUP(A17, Tasks!A$42:E$133,5, FALSE), "") -> Study: Refactor the editDeck view into the static Study view (FlashCard view) | E17: 45012 | F17: Luca | G17: Emile | H17: 1
A18: C2-10 | B18: =IFERROR(VLOOKUP(A18, Tasks!A$42:E$133,2, FALSE), "") -> 2 | C18: =IFERROR(VLOOKUP(A18, Tasks!A$42:E$133,3, FALSE), "") -> C2 | D18: =IFERROR(VLOOKUP(A18, Tasks!A$42:E$133,5, FALSE), "") -> Deck List: Deck creation & deletion from the view | E18: 45012 | F18: Théo | G18: Luca | H18: 2.5
A19: C2-5 | B19: =IFERROR(VLOOKUP(A19, Tasks!A$42:E$133,2, FALSE), "") -> 2 | C19: =IFERROR(VLOOKUP(A19, Tasks!A$42:E$133,3, FALSE), "") -> C2 | D19: =IFERROR(VLOOKUP(A19, Tasks!A$42:E$133,5, FALSE), "") -> EditDeck(FXML): Edit button popup to edit question and answer | E19: 45012 | F19: Antoine | G19: Elliot | H19: 2
A20: C2-1 | B20: =IFERROR(VLOOKUP(A20, Tasks!A$42:E$133,2, FALSE), "") -> 2 | C20: =IFERROR(VLOOKUP(A20, Tasks!A$42:E$133,3, FALSE), "") -> C2 | D20: =IFERROR(VLOOKUP(A20, Tasks!A$42:E$133,5, FALSE), "") -> DB: Create Deck & Card model in database (CRUD) | E20: 45004 | F20: Dave | G20: Anton | H20: 4
A21: D5-1 | B21: 2 | C21: =IFERROR(VLOOKUP(A21, Tasks!A$42:E$133,3, FALSE), "") -> D5 | D21: =IFERROR(VLOOKUP(A21, Tasks!A$42:E$133,5, FALSE), "") -> Refactor: navigation manager design | E21: 45012 | F21: Luca | G21: Antoine | H21: 1
A22: D5-2 | B22: =IFERROR(VLOOKUP(A22, Tasks!A$42:E$133,2, FALSE), "") -> 2 | C22: =IFERROR(VLOOKUP(A22, Tasks!A$42:E$133,3, FALSE), "") -> D5 | D22: =IFERROR(VLOOKUP(A22, Tasks!A$42:E$133,5, FALSE), "") -> Refactor: navigation manager implementation | E22: 45012 | F22: Luca | G22: Antoine | H22: 1
A23: C2-1 | B23: =IFERROR(VLOOKUP(A23, Tasks!A$42:E$133,2, FALSE), "") -> 2 | C23: =IFERROR(VLOOKUP(A23, Tasks!A$42:E$133,3, FALSE), "") -> C2 | D23: =IFERROR(VLOOKUP(A23, Tasks!A$42:E$133,5, FALSE), "") -> DB: Create Deck & Card model in database (CRUD) | E23: 45012 | F23: Dave | G23: Anton | H23: 3
A24: C6-1 | B24: =IFERROR(VLOOKUP(A24, Tasks!A$42:E$133,2, FALSE), "") -> 2 | C24: =IFERROR(VLOOKUP(A24, Tasks!A$42:E$133,3, FALSE), "") -> C6 | D24: =IFERROR(VLOOKUP(A24, Tasks!A$42:E$133,5, FALSE), "") -> Study Mode: Implement the "Review" study mode | E24: 45004 | F24: Ben David | G24: Francesco | H24: 6
A25: C6-2 | B25: =IFERROR(VLOOKUP(A25, Tasks!A$42:E$133,2, FALSE), "") -> 2 | C25: =IFERROR(VLOOKUP(A25, Tasks!A$42:E$133,3, FALSE), "") -> C6 | D25: =IFERROR(VLOOKUP(A25, Tasks!A$42:E$133,5, FALSE), "") -> Study Mode: Implement the "Free" study mode | E25: 45012 | F25: Ben David | G25: Francesco | H25: 4
A26: C2-15 | B26: =IFERROR(VLOOKUP(A26, Tasks!A$42:E$133,2, FALSE), "") -> 2 | C26: =IFERROR(VLOOKUP(A26, Tasks!A$42:E$133,3, FALSE), "") -> C2 | D26: =IFERROR(VLOOKUP(A26, Tasks!A$42:E$133,5, FALSE), "") -> EditDeck(FXML): Add card popup | E26: 45015 | F26: Elliot | G26: Antoine | H26: 0.5
A27: C2-16 | B27: =IFERROR(VLOOKUP(A27, Tasks!A$42:E$133,2, FALSE), "") -> 2 | C27: =IFERROR(VLOOKUP(A27, Tasks!A$42:E$133,3, FALSE), "") -> C2 | D27: =IFERROR(VLOOKUP(A27, Tasks!A$42:E$133,5, FALSE), "") -> EditDeck(FXML): edit title and category popups | E27: 45015 | F27: Elliot | G27: Antoine | H27: 0.5
A28: C2-6 | B28: =IFERROR(VLOOKUP(A28, Tasks!A$42:E$133,2, FALSE), "") -> 2 | C28: =IFERROR(VLOOKUP(A28, Tasks!A$42:E$133,3, FALSE), "") -> C2 | D28: =IFERROR(VLOOKUP(A28, Tasks!A$42:E$133,5, FALSE), "") -> EditDeck(DeckEditController): Edit button logic to edit question and answer in popup | E28: 45015 | F28: Elliot | G28: Antoine | H28: 1
A29: C2-7 | B29: =IFERROR(VLOOKUP(A29, Tasks!A$42:E$133,2, FALSE), "") -> 2 | C29: =IFERROR(VLOOKUP(A29, Tasks!A$42:E$133,3, FALSE), "") -> C2 | D29: =IFERROR(VLOOKUP(A29, Tasks!A$42:E$133,5, FALSE), "") -> EditDeck(FXML): Delete button to delete question | E29: 45015 | F29: Elliot | G29: Antoine | H29: 0.5
A30: C2-8 | B30: =IFERROR(VLOOKUP(A30, Tasks!A$42:E$133,2, FALSE), "") -> 2 | C30: =IFERROR(VLOOKUP(A30, Tasks!A$42:E$133,3, FALSE), "") -> C2 | D30: =IFERROR(VLOOKUP(A30, Tasks!A$42:E$133,5, FALSE), "") -> EditDeck(DeckEditController): Delete button logic to delete question | E30: 45015 | F30: Elliot | G30: Antoine | H30: 0.5
A31: C2-9 | B31: =IFERROR(VLOOKUP(A31, Tasks!A$42:E$133,2, FALSE), "") -> 2 | C31: =IFERROR(VLOOKUP(A31, Tasks!A$42:E$133,3, FALSE), "") -> C2 | D31: =IFERROR(VLOOKUP(A31, Tasks!A$42:E$133,5, FALSE), "") -> EditDeck(DeckEditController) : Edit deck properties logic (title, category) | E31: 45015 | F31: Elliot | G31: Antoine | H31: 0.5
A32: C2-18 | B32: =IFERROR(VLOOKUP(A32, Tasks!A$42:E$133,2, FALSE), "") -> 2 | C32: =IFERROR(VLOOKUP(A32, Tasks!A$42:E$133,3, FALSE), "") -> C2 | D32: =IFERROR(VLOOKUP(A32, Tasks!A$42:E$133,5, FALSE), "") -> EditDeck(FXML): make vboxes question/answer for cards | E32: 45016 | F32: Luca | G32: Antoine | H32: 1
A33: C2-20 | B33: =IFERROR(VLOOKUP(A33, Tasks!A$42:E$133,2, FALSE), "") -> 2 | C33: =IFERROR(VLOOKUP(A33, Tasks!A$42:E$133,3, FALSE), "") -> C2 | D33: =IFERROR(VLOOKUP(A33, Tasks!A$42:E$133,5, FALSE), "") -> EditDeck(FXML): Add scrolling in edit deck view | E33: 45016 | F33: Antoine | G33: Luca | H33: 0.5
... A35: C2-21 | B35: =IFERROR(VLOOKUP(A35, Tasks!A$42:E$133,2, FALSE), "") -> 2 | C35: =IFERROR(VLOOKUP(A35, Tasks!A$42:E$133,3, FALSE), "") -> C2 | D35: =IFERROR(VLOOKUP(A35, Tasks!A$42:E$133,5, FALSE), "") -> DeckList(FXML): Add scrolling in DeckList/Profile/settings view | E35: 45018 | F35: Ismael | G35: Dave | H35: 1
A36: C2-22 | B36: 2 | C36: C2 | D36: DeckList(FXML): text wrapping for DeckList/Profile view | E36: 45018 | F36: Dave | G36: Ismael | H36: 1
A37: C2-23 | B37: =IFERROR(VLOOKUP(A37, Tasks!A$42:E$133,2, FALSE), "") -> 2 | C37: =IFERROR(VLOOKUP(A37, Tasks!A$42:E$133,3, FALSE), "") -> C2 | D37: =IFERROR(VLOOKUP(A37, Tasks!A$42:E$133,5, FALSE), "") -> EditDeck(FXML): add category in view | E37: 45018 | F37: Dave | G37: Ismael | H37: 2
A38: C2-1 | B38: =IFERROR(VLOOKUP(A38, Tasks!A$42:E$133,2, FALSE), "") -> 2 | C38: =IFERROR(VLOOKUP(A38, Tasks!A$42:E$133,3, FALSE), "") -> C2 | D38: =IFERROR(VLOOKUP(A38, Tasks!A$42:E$133,5, FALSE), "") -> DB: Create Deck & Card model in database (CRUD) | E38: 45018 | F38: Anton | G38: Dave | H38: 3
A39: C2-26 | B39: =IFERROR(VLOOKUP(A39, Tasks!A$42:E$133,2, FALSE), "") -> 2 | C39: =IFERROR(VLOOKUP(A39, Tasks!A$42:E$133,3, FALSE), "") -> C2 | D39: =IFERROR(VLOOKUP(A39, Tasks!A$42:E$133,5, FALSE), "") -> Fix(Database): Tables are created only when calling getInstance() | E39: 45018 | F39: Luca | G39: Ismael | H39: 0.5
A40: C2-11 | B40: =IFERROR(VLOOKUP(A40, Tasks!A$42:E$133,2, FALSE), "") -> 2 | C40: =IFERROR(VLOOKUP(A40, Tasks!A$42:E$133,3, FALSE), "") -> C2 | D40: =IFERROR(VLOOKUP(A40, Tasks!A$42:E$133,5, FALSE), "") -> Deck List: Load decks from the database in the view | E40: 45018 | F40: Ismael | G40: Dave | H40: 1
A41: C6-6 | B41: =IFERROR(VLOOKUP(A41, Tasks!A$42:E$133,2, FALSE), "") -> 2 | C41: =IFERROR(VLOOKUP(A41, Tasks!A$42:E$133,3, FALSE), "") -> C6 | D41: =IFERROR(VLOOKUP(A41, Tasks!A$42:E$133,5, FALSE), "") -> Study Mode: create a view for "Free" study mode | E41: 45033 | F41: Théo | G41: Dave | H41: 1.5
A42: D6-1 | B42: =IFERROR(VLOOKUP(A42, Tasks!A$42:E$133,2, FALSE), "") -> 2 | C42: =IFERROR(VLOOKUP(A42, Tasks!A$42:E$133,3, FALSE), "") -> D6 | D42: =IFERROR(VLOOKUP(A42, Tasks!A$42:E$133,5, FALSE), "") -> Refactor: handling all runtime errors in code; replace signature errors in try/catch blocks | E42: 45033 | F42: Francesco | G42: Ismael | H42: 3
...

Sheet Tasks
A1: C stories are Customer Stories D stories are Developer Stories
A2: ID | B2: Iteration | C2: Story | D2: Priority | E2: Task | F2: Pilote | G2: Co-Pilote | H2: Estimate | I2: Real | J2: Deadline | K2: Status | L2: Notes
A3: C1-1 | B3: 1 | C3: C1 | D3: 1 | E3: Mise en place Maven front-end | F3: Luca | G3: Antoine | H3: 0.5 | I3: 1 | K3: Done
A4: C1-2 | B4: 1 | C4: C1 | D4: 1 | E4: Mise en place font custom | F4: Antoine | G4: Luca | H4: 0.25 | I4: 1 | K4: Done
A5: C1-3 | B5: 1 | C5: C1 | D5: 1 | E5: Mise en place classes principales | F5: Luca | G5: Antoine | H5: 0.25 | I5: 0.5 | K5: Done
A6: C1-4 | B6: 1 | C6: C1 | D6: 1 | E6: Création d’un component pour le layout | F6: Luca | G6: Antoine | H6: 0.5 | I6: 1 | K6: Done
A7: C1-5 | B7: 1 | C7: C1 | D7: 1 | E7: Création styles de base | F7: Antoine | G7: Luca | H7: 1 | I7: 2 | K7: Done
A8: C1-6 | B8: 1 | C8: C1 | D8: 1 | E8: Création vue profil | F8: Antoine | G8: Luca | H8: 1 | I8: 1 | K8: Done
A9: C1-7 | B9: 1 | C9: C1 | D9: 1 | E9: Création de la vue settings | F9: Luca | G9: Antoine | H9: 1 | I9: 0.5 | K9: Done
A10: C1-8 | B10: 1 | C10: C1 | D10: 1 | E10: Style vue profil | F10: Antoine | G10: Luca | H10: 1 | I10: 2 | K10: Done
A11: C1-9 | B11: 1 | C11: C1 | D11: 1 | E11: Style vue settings | F11: Luca | G11: Antoine | H11: 1 | I11: 1 | K11: Done
A12: C1-10 | B12: 1 | C12: C1 | D12: 1 | E12: Liaisons avec les vues Login et Signup | F12: Antoine | G12: Luca | H12: 0.5 | I12: 0.5 | K12: Done
A13: C1-11 | B13: 1 | C13: C1 | D13: 1 | E13: Génération dynamique d’éléments UI dans profil et settings | F13: Luca | G13: Antoine | H13: 0.5 | I13: 0.5 | K13: Done
A14: C1-12 | B14: 1 | C14: C1 | D14: 1 | E14: Documentation Javadoc | F14: Antoine | G14: Luca | H14: 0.5 | I14: 1 | K14: Done
... A41: C3-11 | B41: 1 | C41: C3 | D41: 1 | E41: Création de tests pour les classes modèles | F41: Emile | G41: Théo | H41: 1 | I41: 0.5 | K41: Done
A42: C2-1 | B42: 2 | C42: C2 | D42: 1 | E42: DB: Create Deck & Card model in database (CRUD) | F42: Dave | G42: Anton | H42: 2 | I42: =SUMIF(Task_hours!A$4:A$997, A42, Task_hours!H$4:H$997) -> 10 | K42: Done
A43: C2-2 | B43: 2 | C43: C2 | D43: 1 | E43: EditDeck (FXML): Create global title and edit buttons | F43: Elliot | G43: Antoine | H43: 1 | I43: =SUMIF(Task_hours!A$4:A$997, A43, Task_hours!H$4:H$997) -> 1.5 | K43: Done
A44: C2-3 | B44: 2 | C44: C2 | D44: 1 | E44: EditDeck (FXML): Create deck list table | F44: Elliot | G44: Antoine | H44: 2 | I44: =SUMIF(Task_hours!A$4:A$997, A44, Task_hours!H$4:H$997) -> 2.5 | K44: Done
A45: C2-4 | B45: 2 | C45: C2 | D45: 1 | E45: EditDeck (DeckEditController): Load fake deck cards dynamically in list | F45: Antoine | G45: Elliot | H45: 1 | I45: =SUMIF(Task_hours!A$4:A$997, A45, Task_hours!H$4:H$997) -> 0.5 | K45: Done | L45: To be linked with database
A46: C2-5 | B46: 2 | C46: C2 | D46: 1 | E46: EditDeck(FXML): Edit button popup to edit question and answer | F46: Antoine | G46: Elliot | H46: 2 | I46: =SUMIF(Task_hours!A$4:A$997, A46, Task_hours!H$4:H$997) -> 2 | K46: Done
A47: C2-6 | B47: 2 | C47: C2 | D47: 1 | E47: EditDeck(DeckEditController): Edit button logic to edit question and answer in popup | F47: Antoine | G47: Elliot | H47: 2 | I47: =SUMIF(Task_hours!A$4:A$997, A47, Task_hours!H$4:H$997) -> 1 | K47: Done | L47: To be linked with database
A48: C2-7 | B48: 2 | C48: C2 | D48: 1 | E48: EditDeck(FXML): Delete button to delete question | F48: Antoine | G48: Elliot | H48: 1 | I48: =SUMIF(Task_hours!A$4:A$997, A48, Task_hours!H$4:H$997) -> 0.5 | K48: Done
A49: C2-8 | B49: 2 | C49: C2 | D49: 1 | E49: EditDeck(DeckEditController): Delete button logic to delete question | F49: Elliot | G49: Antoine | H49: 2 | I49: =SUMIF(Task_hours!A$4:A$997, A49, Task_hours!H$4:H$997) -> 0.5 | K49: Done
A50: C2-9 | B50: 2 | C50: C2 | D50: 1 | E50: EditDeck(DeckEditController) : Edit deck properties logic (title, category) | F50: Elliot | G50: Antoine | H50: 3 | I50: =SUMIF(Task_hours!A$4:A$997, A50, Task_hours!H$4:H$997) -> 0.5 | K50: Done
A51: C2-10 | B51: 2 | C51: C2 | D51: 1 | E51: Deck List: Deck creation & deletion from the view | F51: Théo | G51: Luca | H51: 3 | I51: =SUMIF(Task_hours!A$4:A$997, A51, Task_hours!H$4:H$997) -> 2.5 | K51: Done
A52: C2-11 | B52: 2 | C52: C2 | D52: 1 | E52: Deck List: Load decks from the database in the view | F52: Théo | G52: Luca | H52: 3 | I52: =SUMIF(Task_hours!A$4:A$997, A52, Task_hours!H$4:H$997) -> 1 | K52: Done
A53: C2-12 | B53: 2 | C53: C2 | D53: 1 | E53: Deck List: Filter deck by category/theme | F53: Antoine | G53: Ismael | H53: 4 | I53: =SUMIF(Task_hours!A$4:A$997, A53, Task_hours!H$4:H$997) -> 3.5 | K53: Done
A54: C2-13 | B54: 2 | C54: C2 | D54: 1 | E54: DeckList (FXML): Delete button warning popup to delete deck & card | F54: Théo | G54: Dave | H54: 1 | I54: =SUMIF(Task_hours!A$4:A$997, A54, Task_hours!H$4:H$997) -> 0.5 | K54: Done
A55: C2-14 | B55: 2 | C55: C2 | D55: 1 | E55: DeckList (ProfileController): Pass deck ID from profile view to deckEdit view when pushing edit btn | F55: Elliot | G55: Antoine | H55: 2 | I55: =SUMIF(Task_hours!A$4:A$997, A55, Task_hours!H$4:H$997) -> 1 | K55: Done | L55: See node.getScene().getWindow() and stage.setUserData()
A56: C2-15 | B56: 2 | C56: C2 | D56: 1 | E56: EditDeck(FXML): Add card popup | F56: Antoine | G56: Elliot | H56: 1 | I56: =SUMIF(Task_hours!A$4:A$997, A56, Task_hours!H$4:H$997) -> 0.5 | K56: Done
A57: C2-16 | B57: 2 | C57: C2 | D57: 1 | E57: EditDeck(FXML): edit title and category popups | F57: Antoine | G57: Elliot | H57: 1 | I57: =SUMIF(Task_hours!A$4:A$997, A57, Task_hours!H$4:H$997) -> 0.5 | K57: Done
A58: C2-18 | B58: 2 | C58: C2 | D58: 1 | E58: EditDeck(FXML): make vboxes question/answer for cards | F58: Luca | G58: Antoine | H58: 2 | I58: =SUMIF(Task_hours!A$4:A$997, A58, Task_hours!H$4:H$997) -> 1 | K58: Done
A59: C2-19 | B59: 2 | C59: C2 | D59: 2 | E59: EditDeck(docs): make docstrings and comments for all classes | F59: Francesco | H59: 2 | I59: =SUMIF(Task_hours!A$4:A$997, A59, Task_hours!H$4:H$997) -> 2.5 | K59: Done
A60: C2-20 | B60: 2 | C60: C2 | D60: 1 | E60: EditDeck(FXML): Add scrolling in edit deck view | F60: Antoine | G60: Luca | H60: 2 | I60: =SUMIF(Task_hours!A$4:A$997, A60, Task_hours!H$4:H$997) -> 0.5 | K60: Done
A61: C2-21 | B61: 2 | C61: C2 | D61: 1 | E61: DeckList(FXML): Add scrolling in DeckList/Profile/settings view | F61: Ismael | G61: Dave | H61: 1.5 | I61: =SUMIF(Task_hours!A$4:A$997, A61, Task_hours!H$4:H$997) -> 1 | K61: Done
A62: C2-22 | B62: 2 | C62: C2 | D62: 1 | E62: DeckList(FXML): text wrapping for DeckList/Profile view | F62: Dave | G62: Ismael | H62: 1 | I62: =SUMIF(Task_hours!A$4:A$997, A62, Task_hours!H$4:H$997) -> 1 | K62: Done
A63: C2-23 | B63: 2 | C63: C2 | D63: 1 | E63: EditDeck(FXML): add category in view | F63: Dave | G63: Ismael | H63: 2 | I63: =SUMIF(Task_hours!A$4:A$997, A63, Task_hours!H$4:H$997) -> 2 | K63: Done
A64: C2-25 | B64: 2 | C64: C2 | D64: 2 | E64: EditDeck(FXML): warning popup before deleting card | F64: Elliot | G64: Antoine | H64: 0.5 | I64: =SUMIF(Task_hours!A$4:A$997, A64, Task_hours!H$4:H$997) -> 0 | K64: Done
A65: C2-26 | B65: 2 | C65: C2 | D65: 1 | E65: Fix(Database): Tables are created only when calling getInstance() | F65: Luca | G65: Ismael | H65: 1 | I65: =SUMIF(Task_hours!A$4:A$997, A65, Task_hours!H$4:H$997) -> 0.5 | K65: Done
A66: C2-27 | B66: 2 | C66: C2 | D66: 1 | E66: DB: Create interface between controller & database for managing decks & cards | F66: Luca | G66: Francesco | H66: 2 | I66: =SUMIF(Task_hours!A$4:A$997, A66, Task_hours!H$4:H$997) -> 3 | K66: Done
...

Sheet Calendar
A1: 2 | B1: Backlog | D1: Progress | F1: Estimated Total | J1: Iteration 2 (Week 1) | X1: Iteration 2 (Week 2) | AL1: Iteration 2 (Week 3)
B2: Estimate/Iteration | D2: Estimate/Iteration | F2: Estimate/Iteration | H2: Total/Iteration | J2: 44999 | L2: 45000 | N2: 45001 | P2: 45002 | R2: 45003 | T2: 45004 | V2: 45012 | X2: 45013 | Z2: 45014 | AB2: 45015 | AD2: 45016 | AF2: 45017 | AH2: 45018 | AJ2: 45033 | AL2: Iteration 2 has no Week 3
A3: Members | B3: P | C3: COP | D3: P | E3: COP | F3: P | G3: COP | H3: P | I3: COP | J3: P | K3: COP | L3: P | M3: COP | N3: P | O3: COP | P3: P | Q3: COP | R3: P | S3: COP | T3: P | U3: COP | V3: P | W3: COP | X3: P | Y3: COP | Z3: P | AA3: COP | AB3: P | AC3: COP | AD3: P | AE3: COP | AF3: P | AG3: COP | AH3: P | AI3: COP | AJ3: P | AK3: COP
A4: Dave | B4: =SUMIFS(Tasks!$H$3:$H1004, Tasks!$F$3:$F1004, $A4, Tasks!$B$3:$B1004, $A$1, Tasks!$K$3:$K1004, "Backlog") -> 0 | C4: =SUMIFS(Tasks!$H$3:$H1004, Tasks!$G$3:$G1004, $A4, Tasks!$B$3:$B1004, $A$1, Tasks!$K$3:$K1004, "Backlog") -> 0 | D4: =SUMIFS(Tasks!$H$3:$H1004, Tasks!$F$3:$F1004, $A4, Tasks!$B$3:$B1004, $A$1, Tasks!$K$3:$K1004, "Progress")-SUMIFS(Tasks!$I$3:$I1004, Tasks!$F$3:$F1004, $A4, Tasks!$B$3:$B1004, $A$1, Tasks!$K$3:$K1004, "Progress") -> 0 | E4: =SUMIFS(Tasks!$H$3:$H1004, Tasks!$G$3:$G1004, $A4, Tasks!$B$3:$B1004, $A$1, Tasks!$K$3:$K1004, "Progress")-SUMIFS(Tasks!$I$3:$I1004, Tasks!$G$3:$G1004, $A4, Tasks!$B$3:$B1004, $A$1, Tasks!$K$3:$K1004, "Progress") -> 0 | F4: =H4+B4 -> 14 | G4: =I4+C4 -> 10 | H4: =SUM(J4,L4,N4,P4,R4,T4,V4,X4,Z4,AB4,AD4,AF4,AH4,AJ4) -> 14 | I4: =SUM(K4,M4,O4,Q4,S4,U4,W4,Y4,AA4,AC4,AE4,AG4,AI4,AK4) -> 10 | J4: =SUMIFS(Task_hours!$H$4:$H$997, Task_hours!$E$4:$E$997, J$2, Task_hours!$F$4:$F$997, $A4) -> 0 | K4: =SUMIFS(Task_hours!$H$4:$H$997, Task_hours!$E$4:$E$997, J$2, Task_hours!$G$4:$G$997, $A4) -> 0 | L4: =SUMIFS(Task_hours!$H$4:$H$997, Task_hours!$E$4:$E$997, L$2, Task_hours!$F$4:$F$997, $A4) -> 0 | M4: =SUMIFS(Task_hours!$H$4:$H$997, Task_hours!$E$4:$E$997, L$2, Task_hours!$G$4:$G$997, $A4) -> 0 | N4: =SUMIFS(Task_hours!$H$4:$H$997, Task_hours!$E$4:$E$997, N$2, Task_hours!$F$4:$F$997, $A4) -> 0 | O4: =SUMIFS(Task_hours!$H$4:$H$997, Task_hours!$E$4:$E$997, N$2, Task_hours!$G$4:$G$997, $A4) -> 0 | P4: =SUMIFS(Task_hours!$H$4:$H$997, Task_hours!$E$4:$E$997, P$2, Task_hours!$F$4:$F$997, $A4) -> 0 | Q4: =SUMIFS(Task_hours!$H$4:$H$997, Task_hours!$E$4:$E$997, P$2, Task_hours!$G$4:$G$997, $A4) -> 3 | R4: =SUMIFS(Task_hours!$H$4:$H$997, Task_hours!$E$4:$E$997, R$2, Task_hours!$F$4:$F$997, $A4) -> 0 | S4: =SUMIFS(Task_hours!$H$4:$H$997, Task_hours!$E$4:$E$997, R$2, Task_hours!$G$4:$G$997, $A4) -> 0 | T4: =SUMIFS(Task_hours!$H$4:$H$997, Task_hours!$E$4:$E$997, T$2, Task_hours!$F$4:$F$997, $A4) -> 4 | U4: =SUMIFS(Task_hours!$H$4:$H$997, Task_hours!$E$4:$E$997, T$2, Task_hours!$G$4:$G$997, $A4) -> 0 | V4: =SUMIFS(Task_hours!$H$4:$H$997, Task_hours!$E$4:$E$997, V$2, Task_hours!$F$4:$F$997, $A4) -> 3 | W4: =SUMIFS(Task_hours!$H$4:$H$997, Task_hours!$E$4:$E$997, V$2, Task_hours!$G$4:$G$997, $A4) -> 0 | X4: =SUMIFS(Task_hours!$H$4:$H$997, Task_hours!$E$4:$E$997, X$2, Task_hours!$F$4:$F$997, $A4) -> 0 | Y4: =SUMIFS(Task_hours!$H$4:$H$997, Task_hours!$E$4:$E$997, X$2, Task_hours!$G$4:$G$997, $A4) -> 0 | Z4: =SUMIFS(Task_hours!$H$4:$H$997, Task_hours!$E$4:$E$997, Z$2, Task_hours!$F$4:$F$997, $A4) -> 0 | AA4: =SUMIFS(Task_hours!$H$4:$H$997, Task_hours!$E$4:$E$997, Z$2, Task_hours!$G$4:$G$997, $A4) -> 0 | AB4: =SUMIFS(Task_hours!$H$4:$H$997, Task_hours!$E$4:$E$997, AB$2, Task_hours!$F$4:$F$997, $A4) -> 0 | AC4: =SUMIFS(Task_hours!$H$4:$H$997, Task_hours!$E$4:$E$997, AB$2, Task_hours!$G$4:$G$997, $A4) -> 0 | AD4: =SUMIFS(Task_hours!$H$4:$H$997, Task_hours!$E$4:$E$997, AD$2, Task_hours!$F$4:$F$997, $A4) -> 0 | AE4: =SUMIFS(Task_hours!$H$4:$H$997, Task_hours!$E$4:$E$997, AD$2, Task_hours!$G$4:$G$997, $A4) -> 0 | AF4: =SUMIFS(Task_hours!$H$4:$H$997, Task_hours!$E$4:$E$997, AF$2, Task_hours!$F$4:$F$997, $A4) -> 0 | AG4: =SUMIFS(Task_hours!$H$4:$H$997, Task_hours!$E$4:$E$997, AF$2, Task_hours!$G$4:$G$997, $A4) -> 0 | AH4: =SUMIFS(Task_hours!$H$4:$H$997, Task_hours!$E$4:$E$997, AH$2, Task_hours!$F$4:$F$997, $A4) -> 3 | AI4: =SUMIFS(Task_hours!$H$4:$H$997, Task_hours!$E$4:$E$997, AH$2, Task_hours!$G$4:$G$997, $A4) -> 5 | AJ4: =SUMIFS(Task_hours!$H$4:$H$997, Task_hours!$E$4:$E$997, AJ$2, Task_hours!$F$4:$F$997, $A4) -> 4 | AK4: =SUMIFS(Task_hours!$H$4:$H$997, Task_hours!$E$4:$E$997, AJ$2, Task_hours!$G$4:$G$997, $A4) -> 2 | AL4: =SUMIFS(Task_hours!$H$4:$H$997, Task_hours!$E$4:$E$997, AL$2, Task_hours!$F$4:$F$997, $A4) -> 0 | AM4: =SUMIFS(Task_hours!$H$4:$H$997, Task_hours!$E$4:$E$997, AL$2, Task_hours!$G$4:$G$997, $A4) -> 0 | AN4: =SUMIFS(Task_hours!$H$4:$H$997, Task_hours!$E$4:$E$997, AN$2, Task_hours!$F$4:$F$997, $A4) -> 0 | AO4: =SUMIFS(Task_hours!$H$4:$H$997, Task_hours!$E$4:$E$997, AN$2, Task_hours!$G$4:$G$997, $A4) -> 0 | AP4: =SUMIFS(Task_hours!$H$4:$H$997, Task_hours!$E$4:$E$997, AP$2, Task_hours!$F$4:$F$997, $A4) -> 0 | AQ4: =SUMIFS(Task_hours!$H$4:$H$997, Task_hours!$E$4:$E$997, AP$2, Task_hours!$G$4:$G$997, $A4) -> 0 | AR4: =SUMIFS(Task_hours!$H$4:$H$997, Task_hours!$E$4:$E$997, AR$2, Task_hours!$F$4:$F$997, $A4) -> 0 | AS4: =SUMIFS(Task_hours!$H$4:$H$997, Task_hours!$E$4:$E$997, AR$2, Task_hours!$G$4:$G$997, $A4) -> 0 | AT4: =SUMIFS(Task_hours!$H$4:$H$997, Task_hours!$E$4:$E$997, AT$2, Task_hours!$F$4:$F$997, $A4) -> 0 | AU4: =SUMIFS(Task_hours!$H$4:$H$997, Task_hours!$E$4:$E$997, AT$2, Task_hours!$G$4:$G$997, $A4) -> 0 | AV4: =SUMIFS(Task_hours!$H$4:$H$997, Task_hours!$E$4:$E$997, AV$2, Task_hours!$F$4:$F$997, $A4) -> 0 | AW4: =SUMIFS(Task_hours!$H$4:$H$997, Task_hours!$E$4:$E$997, AV$2, Task_hours!$G$4:$G$997, $A4) -> 0 | AX4: =SUMIFS(Task_hours!$H$4:$H$997, Task_hours!$E$4:$E$997, AX$2, Task_hours!$F$4:$F$997, $A4) -> 0 | AY4: =SUMIFS(Task_hours!$H$4:$H$997, Task_hours!$E$4:$E$997, AX$2, Task_hours!$G$4:$G$997, $A4) -> 0
A5: Anton | B5: =SUMIFS(Tasks!$H$3:$H1004, Tasks!$F$3:$F1004, $A5, Tasks!$B$3:$B1004, $A$1, Tasks!$K$3:$K1004, "Backlog") -> 0 | C5: =SUMIFS(Tasks!$H$3:$H1004, Tasks!$G$3:$G1004, $A5, Tasks!$B$3:$B1004, $A$1, Tasks!$K$3:$K1004, "Backlog") -> 0 | D5: =SUMIFS(Tasks!$H$3:$H1004, Tasks!$F$3:$F1004, $A5, Tasks!$B$3:$B1004, $A$1, Tasks!$K$3:$K1004, "Progress")-SUMIFS(Tasks!$I$3:$I1004, Tasks!$F$3:$F1004, $A5, Tasks!$B$3:$B1004, $A$1, Tasks!$K$3:$K1004, "Progress") -> 0 | E5: =SUMIFS(Tasks!$H$3:$H1004, Tasks!$G$3:$G1004, $A5, Tasks!$B$3:$B1004, $A$1, Tasks!$K$3:$K1004, "Progress")-SUMIFS(Tasks!$I$3:$I1004, Tasks!$G$3:$G1004, $A5, Tasks!$B$3:$B1004, $A$1, Tasks!$K$3:$K1004, "Progress") -> 0 | F5: =H5+B5 -> 6.5 | G5: =I5+C5 -> 7 | H5: =SUM(J5,L5,N5,P5,R5,T5,V5,X5,Z5,AB5,AD5,AF5,AH5,AJ5) -> 6.5 | I5: =SUM(K5,M5,O5,Q5,S5,U5,W5,Y5,AA5,AC5,AE5,AG5,AI5,AK5) -> 7 | J5: =SUMIFS(Task_hours!$H$4:$H$997, Task_hours!$E$4:$E$997, J$2, Task_hours!$F$4:$F$997, $A5) -> 0 | K5: =SUMIFS(Task_hours!$H$4:$H$997, Task_hours!$E$4:$E$997, J$2, Task_hours!$G$4:$G$997, $A5) -> 0 | L5: =SUMIFS(Task_hours!$H$4:$H$997, Task_hours!$E$4:$E$997, L$2, Task_hours!$F$4:$F$997, $A5) -> 0 | M5: =SUMIFS(Task_hours!$H$4:$H$997, Task_hours!$E$4:$E$997, L$2, Task_hours!$G$4:$G$997, $A5) -> 0 | N5: =SUMIFS(Task_hours!$H$4:$H$997, Task_hours!$E$4:$E$997, N$2, Task_hours!$F$4:$F$997, $A5) -> 0 | O5: =SUMIFS(Task_hours!$H$4:$H$997, Task_hours!$E$4:$E$997, N$2, Task_hours!$G$4:$G$997, $A5) -> 0 | P5: =SUMIFS(Task_hours!$H$4:$H$997, Task_hours!$E$4:$E$997, P$2, Task_hours!$F$4:$F$997, $A5) -> 0 | Q5: =SUMIFS(Task_hours!$H$4:$H$997, Task_hours!$E$4:$E$997, P$2, Task_hours!$G$4:$G$997, $A5) -> 0 | R5: =SUMIFS(Task_hours!$H$4:$H$997, Task_hours!$E$4:$E$997, R$2, Task_hours!$F$4:$F$997, $A5) -> 0 | S5: =SUMIFS(Task_hours!$H$4:$H$997, Task_hours!$E$4:$E$997, R$2, Task_hours!$G$4:$G$997, $A5) -> 0 | T5: =SUMIFS(Task_hours!$H$4:$H$997, Task_hours!$E$4:$E$997, T$2, Task_hours!$F$4:$F$997, $A5) -> 0 | U5: =SUMIFS(Task_hours!$H$4:$H$997, Task_hours!$E$4:$E$997, T$2, Task_hours!$G$4:$G$997, $A5) -> 4 | V5: =SUMIFS(Task_hours!$H$4:$H$997, Task_hours!$E$4:$E$997, V$2, Task_hours!$F$4:$F$997, $A5) -> 0 | W5: =SUMIFS(Task_hours!$H$4:$H$997, Task_hours!$E$4:$E$997, V$2, Task_hours!$G$4:$G$997, $A5) -> 3 | X5: =SUMIFS(Task_hours!$H$4:$H$997, Task_hours!$E$4:$E$997, X$2, Task_hours!$F$4:$F$997, $A5) -> 0 | Y5: =SUMIFS(Task_hours!$H$4:$H$997, Task_hours!$E$4:$E$997, X$2, Task_hours!$G$4:$G$997, $A5) -> 0 | Z5: =SUMIFS(Task_hours!$H$4:$H$997, Task_hours!$E$4:$E$997, Z$2, Task_hours!$F$4:$F$997, $A5) -> 0 | AA5: =SUMIFS(Task_hours!$H$4:$H$997, Task_hours!$E$4:$E$997, Z$2, Task_hours!$G$4:$G$997, $A5) -> 0 | AB5: =SUMIFS(Task_hours!$H$4:$H$997, Task_hours!$E$4:$E$997, AB$2, Task_hours!$F$4:$F$997, $A5) -> 0 | AC5: =SUMIFS(Task_hours!$H$4:$H$997, Task_hours!$E$4:$E$997, AB$2, Task_hours!$G$4:$G$997, $A5) -> 0 | AD5: =SUMIFS(Task_hours!$H$4:$H$997, Task_hours!$E$4:$E$997, AD$2, Task_hours!$F$4:$F$997, $A5) -> 0 | AE5: =SUMIFS(Task_hours!$H$4:$H$997, Task_hours!$E$4:$E$997, AD$2, Task_hours!$G$4:$G$997, $A5) -> 0 | AF5: =SUMIFS(Task_hours!$H$4:$H$997, Task_hours!$E$4:$E$997, AF$2, Task_hours!$F$4:$F$997, $A5) -> 0 | AG5: =SUMIFS(Task_hours!$H$4:$H$997, Task_hours!$E$4:$E$997, AF$2, Task_hours!$G$4:$G$997, $A5) -> 0 | AH5: =SUMIFS(Task_hours!$H$4:$H$997, Task_hours!$E$4:$E$997, AH$2, Task_hours!$F$4:$F$997, $A5) -> 3 | AI5: =SUMIFS(Task_hours!$H$4:$H$997, Task_hours!$E$4:$E$997, AH$2, Task_hours!$G$4:$G$997, $A5) -> 0 | AJ5: =SUMIFS(Task_hours!$H$4:$H$997, Task_hours!$E$4:$E$997, AJ$2, Task_hours!$F$4:$F$997, $A5) -> 3.5 | AK5: =SUMIFS(Task_hours!$H$4:$H$997, Task_hours!$E$4:$E$997, AJ$2, Task_hours!$G$4:$G$997, $A5) -> 0 | AL5: =SUMIFS(Task_hours!$H$4:$H$997, Task_hours!$E$4:$E$997, AL$2, Task_hours!$F$4:$F$997, $A5) -> 0 | AM5: =SUMIFS(Task_hours!$H$4:$H$997, Task_hours!$E$4:$E$997, AL$2, Task_hours!$G$4:$G$997, $A5) -> 0 | AN5: =SUMIFS(Task_hours!$H$4:$H$997, Task_hours!$E$4:$E$997, AN$2, Task_hours!$F$4:$F$997, $A5) -> 0 | AO5: =SUMIFS(Task_hours!$H$4:$H$997, Task_hours!$E$4:$E$997, AN$2, Task_hours!$G$4:$G$997, $A5) -> 0 | AP5: =SUMIFS(Task_hours!$H$4:$H$997, Task_hours!$E$4:$E$997, AP$2, Task_hours!$F$4:$F$997, $A5) -> 0 | AQ5: =SUMIFS(Task_hours!$H$4:$H$997, Task_hours!$E$4:$E$997, AP$2, Task_hours!$G$4:$G$997, $A5) -> 0 | AR5: =SUMIFS(Task_hours!$H$4:$H$997, Task_hours!$E$4:$E$997, AR$2, Task_hours!$F$4:$F$997, $A5) -> 0 | AS5: =SUMIFS(Task_hours!$H$4:$H$997, Task_hours!$E$4:$E$997, AR$2, Task_hours!$G$4:$G$997, $A5) -> 0 | AT5: =SUMIFS(Task_hours!$H$4:$H$997, Task_hours!$E$4:$E$997, AT$2, Task_hours!$F$4:$F$997, $A5) -> 0 | AU5: =SUMIFS(Task_hours!$H$4:$H$997, Task_hours!$E$4:$E$997, AT$2, Task_hours!$G$4:$G$997, $A5) -> 0 | AV5: =SUMIFS(Task_hours!$H$4:$H$997, Task_hours!$E$4:$E$997, AV$2, Task_hours!$F$4:$F$997, $A5) -> 0 | AW5: =SUMIFS(Task_hours!$H$4:$H$997, Task_hours!$E$4:$E$997, AV$2, Task_hours!$G$4:$G$997, $A5) -> 0 | AX5: =SUMIFS(Task_hours!$H$4:$H$997, Task_hours!$E$4:$E$997, AX$2, Task_hours!$F$4:$F$997, $A5) -> 0 | AY5: =SUMIFS(Task_hours!$H$4:$H$997, Task_hours!$E$4:$E$997, AX$2, Task_hours!$G$4:$G$997, $A5) -> 0
A6: Ismael | B6: =SUMIFS(Tasks!$H$3:$H1004, Tasks!$F$3:$F1004, $A6, Tasks!$B$3:$B1004, $A$1, Tasks!$K$3:$K1004, "Backlog") -> 0 | C6: =SUMIFS(Tasks!$H$3:$H1004, Tasks!$G$3:$G1004, $A6, Tasks!$B$3:$B1004, $A$1, Tasks!$K$3:$K1004, "Backlog") -> 0 | D6: =SUMIFS(Tasks!$H$3:$H1004, Tasks!$F$3:$F1004, $A6, Tasks!$B$3:$B1004, $A$1, Tasks!$K$3:$K1004, "Progress")-SUMIFS(Tasks!$I$3:$I1004, Tasks!$F$3:$F1004, $A6, Tasks!$B$3:$B1004, $A$1, Tasks!$K$3:$K1004, "Progress") -> 0 | E6: =SUMIFS(Tasks!$H$3:$H1004, Tasks!$G$3:$G1004, $A6, Tasks!$B$3:$B1004, $A$1, Tasks!$K$3:$K1004, "Progress")-SUMIFS(Tasks!$I$3:$I1004, Tasks!$G$3:$G1004, $A6, Tasks!$B$3:$B1004, $A$1, Tasks!$K$3:$K1004, "Progress") -> 0 | F6: =H6+B6 -> 2 | G6: =I6+C6 -> 11.5 | H6: =SUM(J6,L6,N6,P6,R6,T6,V6,X6,Z6,AB6,AD6,AF6,AH6,AJ6) -> 2 | I6: =SUM(K6,M6,O6,Q6,S6,U6,W6,Y6,AA6,AC6,AE6,AG6,AI6,AK6) -> 11.5 | J6: =SUMIFS(Task_hours!$H$4:$H$997, Task_hours!$E$4:$E$997, J$2, Task_hours!$F$4:$F$997, $A6) -> 0 | K6: =SUMIFS(Task_hours!$H$4:$H$997, Task_hours!$E$4:$E$997, J$2, Task_hours!$G$4:$G$997, $A6) -> 0 | L6: =SUMIFS(Task_hours!$H$4:$H$997, Task_hours!$E$4:$E$997, L$2, Task_hours!$F$4:$F$997, $A6) -> 0 | M6: =SUMIFS(Task_hours!$H$4:$H$997, Task_hours!$E$4:$E$997, L$2, Task_hours!$G$4:$G$997, $A6) -> 0 | N6: =SUMIFS(Task_hours!$H$4:$H$997, Task_hours!$E$4:$E$997, N$2, Task_hours!$F$4:$F$997, $A6) -> 0 | O6: =SUMIFS(Task_hours!$H$4:$H$997, Task_hours!$E$4:$E$997, N$2, Task_hours!$G$4:$G$997, $A6) -> 0 | P6: =SUMIFS(Task_hours!$H$4:$H$997, Task_hours!$E$4:$E$997, P$2, Task_hours!$F$4:$F$997, $A6) -> 0 | Q6: =SUMIFS(Task_hours!$H$4:$H$997, Task_hours!$E$4:$E$997, P$2, Task_hours!$G$4:$G$997, $A6) -> 1 | R6: =SUMIFS(Task_hours!$H$4:$H$997, Task_hours!$E$4:$E$997, R$2, Task_hours!$F$4:$F$997, $A6) -> 0 | S6: =SUMIFS(Task_hours!$H$4:$H$997, Task_hours!$E$4:$E$997, R$2, Task_hours!$G$4:$G$997, $A6) -> 0 | T6: =SUMIFS(Task_hours!$H$4:$H$997, Task_hours!$E$4:$E$997, T$2, Task_hours!$F$4:$F$997, $A6) -> 0 | U6: =SUMIFS(Task_hours!$H$4:$H$997, Task_hours!$E$4:$E$997, T$2, Task_hours!$G$4:$G$997, $A6) -> 0 | V6: =SUMIFS(Task_hours!$H$4:$H$997, Task_hours!$E$4:$E$997, V$2, Task_hours!$F$4:$F$997, $A6) -> 0 | W6: =SUMIFS(Task_hours!$H$4:$H$997, Task_hours!$E$4:$E$997, V$2, Task_hours!$G$4:$G$997, $A6) -> 0 | X6: =SUMIFS(Task_hours!$H$4:$H$997, Task_hours!$E$4:$E$997, X$2, Task_hours!$F$4:$F$997, $A6) -> 0 | Y6: =SUMIFS(Task_hours!$H$4:$H$997, Task_hours!$E$4:$E$997, X$2, Task_hours!$G$4:$G$997, $A6) -> 0 | Z6: =SUMIFS(Task_hours!$H$4:$H$997, Task_hours!$E$4:$E$997, Z$2, Task_hours!$F$4:$F$997, $A6) -> 0 | AA6: =SUMIFS(Task_hours!$H$4:$H$997, Task_hours!$E$4:$E$997, Z$2, Task_hours!$G$4:$G$997, $A6) -> 0 | AB6: =SUMIFS(Task_hours!$H$4:$H$997, Task_hours!$E$4:$E$997, AB$2, Task_hours!$F$4:$F$997, $A6) -> 0 | AC6: =SUMIFS(Task_hours!$H$4:$H$997, Task_hours!$E$4:$E$997, AB$2, Task_hours!$G$4:$G$997, $A6) -> 0 | AD6: =SUMIFS(Task_hours!$H$4:$H$997, Task_hours!$E$4:$E$997, AD$2, Task_hours!$F$4:$F$997, $A6) -> 0 | AE6: =SUMIFS(Task_hours!$H$4:$H$997, Task_hours!$E$4:$E$997, AD$2, Task_hours!$G$4:$G$997, $A6) -> 0 | AF6: =SUMIFS(Task_hours!$H$4:$H$997, Task_hours!$E$4:$E$997, AF$2, Task_hours!$F$4:$F$997, $A6) -> 0 | AG6: =SUMIFS(Task_hours!$H$4:$H$997, Task_hours!$E$4:$E$997, AF$2, Task_hours!$G$4:$G$997, $A6) -> 0 | AH6: =SUMIFS(Task_hours!$H$4:$H$997, Task_hours!$E$4:$E$997, AH$2, Task_hours!$F$4:$F$997, $A6) -> 2 | AI6: =SUMIFS(Task_hours!$H$4:$H$997, Task_hours!$E$4:$E$997, AH$2, Task_hours!$G$4:$G$997, $A6) -> 3.5 | AJ6: =SUMIFS(Task_hours!$H$4:$H$997, Task_hours!$E$4:$E$997, AJ$2, Task_hours!$F$4:$F$997, $A6) -> 0 | AK6: =SUMIFS(Task_hours!$H$4:$H$997, Task_hours!$E$4:$E$997, AJ$2, Task_hours!$G$4:$G$997, $A6) -> 7 | AL6: =SUMIFS(Task_hours!$H$4:$H$997, Task_hours!$E$4:$E$997, AL$2, Task_hours!$F$4:$F$997, $A6) -> 0 | AM6: =SUMIFS(Task_hours!$H$4:$H$997, Task_hours!$E$4:$E$997, AL$2, Task_hours!$G$4:$G$997, $A6) -> 0 | AN6: =SUMIFS(Task_hours!$H$4:$H$997, Task_hours!$E$4:$E$997, AN$2, Task_hours!$F$4:$F$997, $A6) -> 0 | AO6: =SUMIFS(Task_hours!$H$4:$H$997, Task_hours!$E$4:$E$997, AN$2, Task_hours!$G$4:$G$997, $A6) -> 0 | AP6: =SUMIFS(Task_hours!$H$4:$H$997, Task_hours!$E$4:$E$997, AP$2, Task_hours!$F$4:$F$997, $A6) -> 0 | AQ6: =SUMIFS(Task_hours!$H$4:$H$997, Task_hours!$E$4:$E$997, AP$2, Task_hours!$G$4:$G$997, $A6) -> 0 | AR6: =SUMIFS(Task_hours!$H$4:$H$997, Task_hours!$E$4:$E$997, AR$2, Task_hours!$F$4:$F$997, $A6) -> 0 | AS6: =SUMIFS(Task_hours!$H$4:$H$997, Task_hours!$E$4:$E$997, AR$2, Task_hours!$G$4:$G$997, $A6) -> 0 | AT6: =SUMIFS(Task_hours!$H$4:$H$997, Task_hours!$E$4:$E$997, AT$2, Task_hours!$F$4:$F$997, $A6) -> 0 | AU6: =SUMIFS(Task_hours!$H$4:$H$997, Task_hours!$E$4:$E$997, AT$2, Task_hours!$G$4:$G$997, $A6) -> 0 | AV6: =SUMIFS(Task_hours!$H$4:$H$997, Task_hours!$E$4:$E$997, AV$2, Task_hours!$F$4:$F$997, $A6) -> 0 | AW6: =SUMIFS(Task_hours!$H$4:$H$997, Task_hours!$E$4:$E$997, AV$2, Task_hours!$G$4:$G$997, $A6) -> 0 | AX6: =SUMIFS(Task_hours!$H$4:$H$997, Task_hours!$E$4:$E$997, AX$2, Task_hours!$F$4:$F$997, $A6) -> 0 | AY6: =SUMIFS(Task_hours!$H$4:$H$997, Task_hours!$E$4:$E$997, AX$2, Task_hours!$G$4:$G$997, $A6) -> 0
A7: Luca | B7: =SUMIFS(Tasks!$H$3:$H1004, Tasks!$F$3:$F1004, $A7, Tasks!$B$3:$B1004, $A$1, Tasks!$K$3:$K1004, "Backlog") -> 0 | C7: =SUMIFS(Tasks!$H$3:$H1004, Tasks!$G$3:$G1004, $A7, Tasks!$B$3:$B1004, $A$1, Tasks!$K$3:$K1004, "Backlog") -> 0 | D7: =SUMIFS(Tasks!$H$3:$H1004, Tasks!$F$3:$F1004, $A7, Tasks!$B$3:$B1004, $A$1, Tasks!$K$3:$K1004, "Progress")-SUMIFS(Tasks!$I$3:$I1004, Tasks!$F$3:$F1004, $A7, Tasks!$B$3:$B1004, $A$1, Tasks!$K$3:$K1004, "Progress") -> 0 | E7: =SUMIFS(Tasks!$H$3:$H1004, Tasks!$G$3:$G1004, $A7, Tasks!$B$3:$B1004, $A$1, Tasks!$K$3:$K1004, "Progress")-SUMIFS(Tasks!$I$3:$I1004, Tasks!$G$3:$G1004, $A7, Tasks!$B$3:$B1004, $A$1, Tasks!$K$3:$K1004, "Progress") -> 0 | F7: =H7+B7 -> 15.5 | G7: =I7+C7 -> 8 | H7: =SUM(J7,L7,N7,P7,R7,T7,V7,X7,Z7,AB7,AD7,AF7,AH7,AJ7) -> 15.5 | I7: =SUM(K7,M7,O7,Q7,S7,U7,W7,Y7,AA7,AC7,AE7,AG7,AI7,AK7) -> 8 | J7: =SUMIFS(Task_hours!$H$4:$H$997, Task_hours!$E$4:$E$997, J$2, Task_hours!$F$4:$F$997, $A7) -> 0 | K7: =SUMIFS(Task_hours!$H$4:$H$997, Task_hours!$E$4:$E$997, J$2, Task_hours!$G$4:$G$997, $A7) -> 0 | L7: =SUMIFS(Task_hours!$H$4:$H$997, Task_hours!$E$4:$E$997, L$2, Task_hours!$F$4:$F$997, $A7) -> 0 | M7: =SUMIFS(Task_hours!$H$4:$H$997, Task_hours!$E$4:$E$997, L$2, Task_hours!$G$4:$G$997, $A7) -> 0 | N7: =SUMIFS(Task_hours!$H$4:$H$997, Task_hours!$E$4:$E$997, N$2, Task_hours!$F$4:$F$997, $A7) -> 1 | O7: =SUMIFS(Task_hours!$H$4:$H$997, Task_hours!$E$4:$E$997, N$2, Task_hours!$G$4:$G$997, $A7) -> 1 | P7: =SUMIFS(Task_hours!$H$4:$H$997, Task_hours!$E$4:$E$997, P$2, Task_hours!$F$4:$F$997, $A7) -> 1 | Q7: =SUMIFS(Task_hours!$H$4:$H$997, Task_hours!$E$4:$E$997, P$2, Task_hours!$G$4:$G$997, $A7) -> 0 | R7: =SUMIFS(Task_hours!$H$4:$H$997, Task_hours!$E$4:$E$997, R$2, Task_hours!$F$4:$F$997, $A7) -> 0 | S7: =SUMIFS(Task_hours!$H$4:$H$997, Task_hours!$E$4:$E$997, R$2, Task_hours!$G$4:$G$997, $A7) -> 0 | T7: =SUMIFS(Task_hours!$H$4:$H$997, Task_hours!$E$4:$E$997, T$2, Task_hours!$F$4:$F$997, $A7) -> 2 | U7: =SUMIFS(Task_hours!$H$4:$H$997, Task_hours!$E$4:$E$997, T$2, Task_hours!$G$4:$G$997, $A7) -> 0 | V7: =SUMIFS(Task_hours!$H$4:$H$997, Task_hours!$E$4:$E$997, V$2, Task_hours!$F$4:$F$997, $A7) -> 3 | W7: =SUMIFS(Task_hours!$H$4:$H$997, Task_hours!$E$4:$E$997, V$2, Task_hours!$G$4:$G$997, $A7) -> 2.5 | X7: =SUMIFS(Task_hours!$H$4:$H$997, Task_hours!$E$4:$E$997, X$2, Task_hours!$F$4:$F$997, $A7) -> 0 | Y7: =SUMIFS(Task_hours!$H$4:$H$997, Task_hours!$E$4:$E$997, X$2, Task_hours!$G$4:$G$997, $A7) -> 0 | Z7: =SUMIFS(Task_hours!$H$4:$H$997, Task_hours!$E$4:$E$997, Z$2, Task_hours!$F$4:$F$997, $A7) -> 0 | AA7: =SUMIFS(Task_hours!$H$4:$H$997, Task_hours!$E$4:$E$997, Z$2, Task_hours!$G$4:$G$997, $A7) -> 0 | AB7: =SUMIFS(Task_hours!$H$4:$H$997, Task_hours!$E$4:$E$997, AB$2, Task_hours!$F$4:$F$997, $A7) -> 0 | AC7: =SUMIFS(Task_hours!$H$4:$H$997, Task_hours!$E$4:$E$997, AB$2, Task_hours!$G$4:$G$997, $A7) -> 0 | AD7: =SUMIFS(Task_hours!$H$4:$H$997, Task_hours!$E$4:$E$997, AD$2, Task_hours!$F$4:$F$997, $A7) -> 1 | AE7: =SUMIFS(Task_hours!$H$4:$H$997, Task_hours!$E$4:$E$997, AD$2, Task_hours!$G$4:$G$997, $A7) -> 0.5 | AF7: =SUMIFS(Task_hours!$H$4:$H$997, Task_hours!$E$4:$E$997, AF$2, Task_hours!$F$4:$F$997, $A7) -> 0 | AG7: =SUMIFS(Task_hours!$H$4:$H$997, Task_hours!$E$4:$E$997, AF$2, Task_hours!$G$4:$G$997, $A7) -> 0 | AH7: =SUMIFS(Task_hours!$H$4:$H$997, Task_hours!$E$4:$E$997, AH$2, Task_hours!$F$4:$F$997, $A7) -> 0.5 | AI7: =SUMIFS(Task_hours!$H$4:$H$997, Task_hours!$E$4:$E$997, AH$2, Task_hours!$G$4:$G$997, $A7) -> 0 | AJ7: =SUMIFS(Task_hours!$H$4:$H$997, Task_hours!$E$4:$E$997, AJ$2, Task_hours!$F$4:$F$997, $A7) -> 7 | AK7: =SUMIFS(Task_hours!$H$4:$H$997, Task_hours!$E$4:$E$997, AJ$2, Task_hours!$G$4:$G$997, $A7) -> 4 | AL7: =SUMIFS(Task_hours!$H$4:$H$997, Task_hours!$E$4:$E$997, AL$2, Task_hours!$F$4:$F$997, $A7) -> 0 | AM7: =SUMIFS(Task_hours!$H$4:$H$997, Task_hours!$E$4:$E$997, AL$2, Task_hours!$G$4:$G$997, $A7) -> 0 | AN7: =SUMIFS(Task_hours!$H$4:$H$997, Task_hours!$E$4:$E$997, AN$2, Task_hours!$F$4:$F$997, $A7) -> 0 | AO7: =SUMIFS(Task_hours!$H$4:$H$997, Task_hours!$E$4:$E$997, AN$2, Task_hours!$G$4:$G$997, $A7) -> 0 | AP7: =SUMIFS(Task_hours!$H$4:$H$997, Task_hours!$E$4:$E$997, AP$2, Task_hours!$F$4:$F$997, $A7) -> 0 | AQ7: =SUMIFS(Task_hours!$H$4:$H$997, Task_hours!$E$4:$E$997, AP$2, Task_hours!$G$4:$G$997, $A7) -> 0 | AR7: =SUMIFS(Task_hours!$H$4:$H$997, Task_hours!$E$4:$E$997, AR$2, Task_hours!$F$4:$F$997, $A7) -> 0 | AS7: =SUMIFS(Task_hours!$H$4:$H$997, Task_hours!$E$4:$E$997, AR$2, Task_hours!$G$4:$G$997, $A7) -> 0 | AT7: =SUMIFS(Task_hours!$H$4:$H$997, Task_hours!$E$4:$E$997, AT$2, Task_hours!$F$4:$F$997, $A7) -> 0 | AU7: =SUMIFS(Task_hours!$H$4:$H$997, Task_hours!$E$4:$E$997, AT$2, Task_hours!$G$4:$G$997, $A7) -> 0 | AV7: =SUMIFS(Task_hours!$H$4:$H$997, Task_hours!$E$4:$E$997, AV$2, Task_hours!$F$4:$F$997, $A7) -> 0 | AW7: =SUMIFS(Task_hours!$H$4:$H$997, Task_hours!$E$4:$E$997, AV$2, Task_hours!$G$4:$G$997, $A7) -> 0 | AX7: =SUMIFS(Task_hours!$H$4:$H$997, Task_hours!$E$4:$E$997, AX$2, Task_hours!$F$4:$F$997, $A7) -> 0 | AY7: =SUMIFS(Task_hours!$H$4:$H$997, Task_hours!$E$4:$E$997, AX$2, Task_hours!$G$4:$G$997, $A7) -> 0
A8: Antoine | B8: =SUMIFS(Tasks!$H$3:$H1004, Tasks!$F$3:$F1004, $A8, Tasks!$B$3:$B1004, $A$1, Tasks!$K$3:$K1004, "Backlog") -> 0 | C8: =SUMIFS(Tasks!$H$3:$H1004, Tasks!$G$3:$G1004, $A8, Tasks!$B$3:$B1004, $A$1, Tasks!$K$3:$K1004, "Backlog") -> 0 | D8: =SUMIFS(Tasks!$H$3:$H1004, Tasks!$F$3:$F1004, $A8, Tasks!$B$3:$B1004, $A$1, Tasks!$K$3:$K1004, "Progress")-SUMIFS(Tasks!$I$3:$I1004, Tasks!$F$3:$F1004, $A8, Tasks!$B$3:$B1004, $A$1, Tasks!$K$3:$K1004, "Progress") -> 0 | E8: =SUMIFS(Tasks!$H$3:$H1004, Tasks!$G$3:$G1004, $A8, Tasks!$B$3:$B1004, $A$1, Tasks!$K$3:$K1004, "Progress")-SUMIFS(Tasks!$I$3:$I1004, Tasks!$G$3:$G1004, $A8, Tasks!$B$3:$B1004, $A$1, Tasks!$K$3:$K1004, "Progress") -> 0 | F8: =H8+B8 -> 11.5 | G8: =I8+C8 -> 11 | H8: =SUM(J8,L8,N8,P8,R8,T8,V8,X8,Z8,AB8,AD8,AF8,AH8,AJ8) -> 11.5 | I8: =SUM(K8,M8,O8,Q8,S8,U8,W8,Y8,AA8,AC8,AE8,AG8,AI8,AK8) -> 11 | J8: =SUMIFS(Task_hours!$H$4:$H$997, Task_hours!$E$4:$E$997, J$2, Task_hours!$F$4:$F$997, $A8) -> 0 | K8: =SUMIFS(Task_hours!$H$4:$H$997, Task_hours!$E$4:$E$997, J$2, Task_hours!$G$4:$G$997, $A8) -> 0 | L8: =SUMIFS(Task_hours!$H$4:$H$997, Task_hours!$E$4:$E$997, L$2, Task_hours!$F$4:$F$997, $A8) -> 0 | M8: =SUMIFS(Task_hours!$H$4:$H$997, Task_hours!$E$4:$E$997, L$2, Task_hours!$G$4:$G$997, $A8) -> 0 | N8: =SUMIFS(Task_hours!$H$4:$H$997, Task_hours!$E$4:$E$997, N$2, Task_hours!$F$4:$F$997, $A8) -> 2 | O8: =SUMIFS(Task_hours!$H$4:$H$997, Task_hours!$E$4:$E$997, N$2, Task_hours!$G$4:$G$997, $A8) -> 2 | P8: =SUMIFS(Task_hours!$H$4:$H$997, Task_hours!$E$4:$E$997, P$2, Task_hours!$F$4:$F$997, $A8) -> 0 | Q8: =SUMIFS(Task_hours!$H$4:$H$997, Task_hours!$E$4:$E$997, P$2, Task_hours!$G$4:$G$997, $A8) -> 1 | R8: =SUMIFS(Task_hours!$H$4:$H$997, Task_hours!$E$4:$E$997, R$2, Task_hours!$F$4:$F$997, $A8) -> 0 | S8: =SUMIFS(Task_hours!$H$4:$H$997, Task_hours!$E$4:$E$997, R$2, Task_hours!$G$4:$G$997, $A8) -> 0 | T8: =SUMIFS(Task_hours!$H$4:$H$997, Task_hours!$E$4:$E$997, T$2, Task_hours!$F$4:$F$997, $A8) -> 3.5 | U8: =SUMIFS(Task_hours!$H$4:$H$997, Task_hours!$E$4:$E$997, T$2, Task_hours!$G$4:$G$997, $A8) -> 0 | V8: =SUMIFS(Task_hours!$H$4:$H$997, Task_hours!$E$4:$E$997, V$2, Task_hours!$F$4:$F$997, $A8) -> 2 | W8: =SUMIFS(Task_hours!$H$4:$H$997, Task_hours!$E$4:$E$997, V$2, Task_hours!$G$4:$G$997, $A8) -> 2 | X8: =SUMIFS(Task_hours!$H$4:$H$997, Task_hours!$E$4:$E$997, X$2, Task_hours!$F$4:$F$997, $A8) -> 0 | Y8: =SUMIFS(Task_hours!$H$4:$H$997, Task_hours!$E$4:$E$997, X$2, Task_hours!$G$4:$G$997, $A8) -> 0 | Z8: =SUMIFS(Task_hours!$H$4:$H$997, Task_hours!$E$4:$E$997, Z$2, Task_hours!$F$4:$F$997, $A8) -> 0 | AA8: =SUMIFS(Task_hours!$H$4:$H$997, Task_hours!$E$4:$E$997, Z$2, Task_hours!$G$4:$G$997, $A8) -> 0 | AB8: =SUMIFS(Task_hours!$H$4:$H$997, Task_hours!$E$4:$E$997, AB$2, Task_hours!$F$4:$F$997, $A8) -> 0 | AC8: =SUMIFS(Task_hours!$H$4:$H$997, Task_hours!$E$4:$E$997, AB$2, Task_hours!$G$4:$G$997, $A8) -> 3.5 | AD8: =SUMIFS(Task_hours!$H$4:$H$997, Task_hours!$E$4:$E$997, AD$2, Task_hours!$F$4:$F$997, $A8) -> 0.5 | AE8: =SUMIFS(Task_hours!$H$4:$H$997, Task_hours!$E$4:$E$997, AD$2, Task_hours!$G$4:$G$997, $A8) -> 1 | AF8: =SUMIFS(Task_hours!$H$4:$H$997, Task_hours!$E$4:$E$997, AF$2, Task_hours!$F$4:$F$997, $A8) -> 0 | AG8: =SUMIFS(Task_hours!$H$4:$H$997, Task_hours!$E$4:$E$997, AF$2, Task_hours!$G$4:$G$997, $A8) -> 0 | AH8: =SUMIFS(Task_hours!$H$4:$H$997, Task_hours!$E$4:$E$997, AH$2, Task_hours!$F$4:$F$997, $A8) -> 0 | AI8: =SUMIFS(Task_hours!$H$4:$H$997, Task_hours!$E$4:$E$997, AH$2, Task_hours!$G$4:$G$997, $A8) -> 0 | AJ8: =SUMIFS(Task_hours!$H$4:$H$997, Task_hours!$E$4:$E$997, AJ$2, Task_hours!$F$4:$F$997, $A8) -> 3.5 | AK8: =SUMIFS(Task_hours!$H$4:$H$997, Task_hours!$E$4:$E$997, AJ$2, Task_hours!$G$4:$G$997, $A8) -> 1.5 | AL8: =SUMIFS(Task_hours!$H$4:$H$997, Task_hours!$E$4:$E$997, AL$2, Task_hours!$F$4:$F$997, $A8) -> 0 | AM8: =SUMIFS(Task_hours!$H$4:$H$997, Task_hours!$E$4:$E$997, AL$2, Task_hours!$G$4:$G$997, $A8) -> 0 | AN8: =SUMIFS(Task_hours!$H$4:$H$997, Task_hours!$E$4:$E$997, AN$2, Task_hours!$F$4:$F$997, $A8) -> 0 | AO8: =SUMIFS(Task_hours!$H$4:$H$997, Task_hours!$E$4:$E$997, AN$2, Task_hours!$G$4:$G$997, $A8) -> 0 | AP8: =SUMIFS(Task_hours!$H$4:$H$997, Task_hours!$E$4:$E$997, AP$2, Task_hours!$F$4:$F$997, $A8) -> 0 | AQ8: =SUMIFS(Task_hours!$H$4:$H$997, Task_hours!$E$4:$E$997, AP$2, Task_hours!$G$4:$G$997, $A8) -> 0 | AR8: =SUMIFS(Task_hours!$H$4:$H$997, Task_hours!$E$4:$E$997, AR$2, Task_hours!$F$4:$F$997, $A8) -> 0 | AS8: =SUMIFS(Task_hours!$H$4:$H$997, Task_hours!$E$4:$E$997, AR$2, Task_hours!$G$4:$G$997, $A8) -> 0 | AT8: =SUMIFS(Task_hours!$H$4:$H$997, Task_hours!$E$4:$E$997, AT$2, Task_hours!$F$4:$F$997, $A8) -> 0 | AU8: =SUMIFS(Task_hours!$H$4:$H$997, Task_hours!$E$4:$E$997, AT$2, Task_hours!$G$4:$G$997, $A8) -> 0 | AV8: =SUMIFS(Task_hours!$H$4:$H$997, Task_hours!$E$4:$E$997, AV$2, Task_hours!$F$4:$F$997, $A8) -> 0 | AW8: =SUMIFS(Task_hours!$H$4:$H$997, Task_hours!$E$4:$E$997, AV$2, Task_hours!$G$4:$G$997, $A8) -> 0 | AX8: =SUMIFS(Task_hours!$H$4:$H$997, Task_hours!$E$4:$E$997, AX$2, Task_hours!$F$4:$F$997, $A8) -> 0 | AY8: =SUMIFS(Task_hours!$H$4:$H$997, Task_hours!$E$4:$E$997, AX$2, Task_hours!$G$4:$G$997, $A8) -> 0
A9: Ben David | B9: =SUMIFS(Tasks!$H$3:$H1004, Tasks!$F$3:$F1004, $A9, Tasks!$B$3:$B1004, $A$1, Tasks!$K$3:$K1004, "Backlog") -> 0 | C9: =SUMIFS(Tasks!$H$3:$H1004, Tasks!$G$3:$G1004, $A9, Tasks!$B$3:$B1004, $A$1, Tasks!$K$3:$K1004, "Backlog") -> 0 | D9: =SUMIFS(Tasks!$H$3:$H1004, Tasks!$F$3:$F1004, $A9, Tasks!$B$3:$B1004, $A$1, Tasks!$K$3:$K1004, "Progress")-SUMIFS(Tasks!$I$3:$I1004, Tasks!$F$3:$F1004, $A9, Tasks!$B$3:$B1004, $A$1, Tasks!$K$3:$K1004, "Progress") -> 0 | E9: =SUMIFS(Tasks!$H$3:$H1004, Tasks!$G$3:$G1004, $A9, Tasks!$B$3:$B1004, $A$1, Tasks!$K$3:$K1004, "Progress")-SUMIFS(Tasks!$I$3:$I1004, Tasks!$G$3:$G1004, $A9, Tasks!$B$3:$B1004, $A$1, Tasks!$K$3:$K1004, "Progress") -> 0 | F9: =H9+B9 -> 10 | G9: =I9+C9 -> 7.5 | H9: =SUM(J9,L9,N9,P9,R9,T9,V9,X9,Z9,AB9,AD9,AF9,AH9,AJ9) -> 10 | I9: =SUM(K9,M9,O9,Q9,S9,U9,W9,Y9,AA9,AC9,AE9,AG9,AI9,AK9) -> 7.5 | J9: =SUMIFS(Task_hours!$H$4:$H$997, Task_hours!$E$4:$E$997, J$2, Task_hours!$F$4:$F$997, $A9) -> 0 | K9: =SUMIFS(Task_hours!$H$4:$H$997, Task_hours!$E$4:$E$997, J$2, Task_hours!$G$4:$G$997, $A9) -> 0 | L9: =SUMIFS(Task_hours!$H$4:$H$997, Task_hours!$E$4:$E$997, L$2, Task_hours!$F$4:$F$997, $A9) -> 0 | M9: =SUMIFS(Task_hours!$H$4:$H$997, Task_hours!$E$4:$E$997, L$2, Task_hours!$G$4:$G$997, $A9) -> 0 | N9: =SUMIFS(Task_hours!$H$4:$H$997, Task_hours!$E$4:$E$997, N$2, Task_hours!$F$4:$F$997, $A9) -> 0 | O9: =SUMIFS(Task_hours!$H$4:$H$997, Task_hours!$E$4:$E$997, N$2, Task_hours!$G$4:$G$997, $A9) -> 0 | P9: =SUMIFS(Task_hours!$H$4:$H$997, Task_hours!$E$4:$E$997, P$2, Task_hours!$F$4:$F$997, $A9) -> 0 | Q9: =SUMIFS(Task_hours!$H$4:$H$997, Task_hours!$E$4:$E$997, P$2, Task_hours!$G$4:$G$997, $A9) -> 0 | R9: =SUMIFS(Task_hours!$H$4:$H$997, Task_hours!$E$4:$E$997, R$2, Task_hours!$F$4:$F$997, $A9) -> 0 | S9: =SUMIFS(Task_hours!$H$4:$H$997, Task_hours!$E$4:$E$997, R$2, Task_hours!$G$4:$G$997, $A9) -> 0 | T9: =SUMIFS(Task_hours!$H$4:$H$997, Task_hours!$E$4:$E$997, T$2, Task_hours!$F$4:$F$997, $A9) -> 6 | U9: =SUMIFS(Task_hours!$H$4:$H$997, Task_hours!$E$4:$E$997, T$2, Task_hours!$G$4:$G$997, $A9) -> 0 | V9: =SUMIFS(Task_hours!$H$4:$H$997, Task_hours!$E$4:$E$997, V$2, Task_hours!$F$4:$F$997, $A9) -> 4 | W9: =SUMIFS(Task_hours!$H$4:$H$997, Task_hours!$E$4:$E$997, V$2, Task_hours!$G$4:$G$997, $A9) -> 0 | X9: =SUMIFS(Task_hours!$H$4:$H$997, Task_hours!$E$4:$E$997, X$2, Task_hours!$F$4:$F$997, $A9) -> 0 | Y9: =SUMIFS(Task_hours!$H$4:$H$997, Task_hours!$E$4:$E$997, X$2, Task_hours!$G$4:$G$997, $A9) -> 2.5 | Z9: =SUMIFS(Task_hours!$H$4:$H$997, Task_hours!$E$4:$E$997, Z$2, Task_hours!$F$4:$F$997, $A9) -> 0 | AA9: =SUMIFS(Task_hours!$H$4:$H$997, Task_hours!$E$4:$E$997, Z$2, Task_hours!$G$4:$G$997, $A9) -> 1.5 | AB9: =SUMIFS(Task_hours!$H$4:$H$997, Task_hours!$E$4:$E$997, AB$2, Task_hours!$F$4:$F$997, $A9) -> 0 | AC9: =SUMIFS(Task_hours!$H$4:$H$997, Task_hours!$E$4:$E$997, AB$2, Task_hours!$G$4:$G$997, $A9) -> 0 | AD9: =SUMIFS(Task_hours!$H$4:$H$997, Task_hours!$E$4:$E$997, AD$2, Task_hours!$F$4:$F$997, $A9) -> 0 | AE9: =SUMIFS(Task_hours!$H$4:$H$997, Task_hours!$E$4:$E$997, AD$2, Task_hours!$G$4:$G$997, $A9) -> 0 | AF9: =SUMIFS(Task_hours!$H$4:$H$997, Task_hours!$E$4:$E$997, AF$2, Task_hours!$F$4:$F$997, $A9) -> 0 | AG9: =SUMIFS(Task_hours!$H$4:$H$997, Task_hours!$E$4:$E$997, AF$2, Task_hours!$G$4:$G$997, $A9) -> 0 | AH9: =SUMIFS(Task_hours!$H$4:$H$997, Task_hours!$E$4:$E$997, AH$2, Task_hours!$F$4:$F$997, $A9) -> 0 | AI9: =SUMIFS(Task_hours!$H$4:$H$997, Task_hours!$E$4:$E$997, AH$2, Task_hours!$G$4:$G$997, $A9) -> 0 | AJ9: =SUMIFS(Task_hours!$H$4:$H$997, Task_hours!$E$4:$E$997, AJ$2, Task_hours!$F$4:$F$997, $A9) -> 0 | AK9: =SUMIFS(Task_hours!$H$4:$H$997, Task_hours!$E$4:$E$997, AJ$2, Task_hours!$G$4:$G$997, $A9) -> 3.5 | AL9: =SUMIFS(Task_hours!$H$4:$H$997, Task_hours!$E$4:$E$997, AL$2, Task_hours!$F$4:$F$997, $A9) -> 0 | AM9: =SUMIFS(Task_hours!$H$4:$H$997, Task_hours!$E$4:$E$997, AL$2, Task_hours!$G$4:$G$997, $A9) -> 0 | AN9: =SUMIFS(Task_hours!$H$4:$H$997, Task_hours!$E$4:$E$997, AN$2, Task_hours!$F$4:$F$997, $A9) -> 0 | AO9: =SUMIFS(Task_hours!$H$4:$H$997, Task_hours!$E$4:$E$997, AN$2, Task_hours!$G$4:$G$997, $A9) -> 0 | AP9: =SUMIFS(Task_hours!$H$4:$H$997, Task_hours!$E$4:$E$997, AP$2, Task_hours!$F$4:$F$997, $A9) -> 0 | AQ9: =SUMIFS(Task_hours!$H$4:$H$997, Task_hours!$E$4:$E$997, AP$2, Task_hours!$G$4:$G$997, $A9) -> 0 | AR9: =SUMIFS(Task_hours!$H$4:$H$997, Task_hours!$E$4:$E$997, AR$2, Task_hours!$F$4:$F$997, $A9) -> 0 | AS9: =SUMIFS(Task_hours!$H$4:$H$997, Task_hours!$E$4:$E$997, AR$2, Task_hours!$G$4:$G$997, $A9) -> 0 | AT9: =SUMIFS(Task_hours!$H$4:$H$997, Task_hours!$E$4:$E$997, AT$2, Task_hours!$F$4:$F$997, $A9) -> 0 | AU9: =SUMIFS(Task_hours!$H$4:$H$997, Task_hours!$E$4:$E$997, AT$2, Task_hours!$G$4:$G$997, $A9) -> 0 | AV9: =SUMIFS(Task_hours!$H$4:$H$997, Task_hours!$E$4:$E$997, AV$2, Task_hours!$F$4:$F$997, $A9) -> 0 | AW9: =SUMIFS(Task_hours!$H$4:$H$997, Task_hours!$E$4:$E$997, AV$2, Task_hours!$G$4:$G$997, $A9) -> 0 | AX9: =SUMIFS(Task_hours!$H$4:$H$997, Task_hours!$E$4:$E$997, AX$2, Task_hours!$F$4:$F$997, $A9) -> 0 | AY9: =SUMIFS(Task_hours!$H$4:$H$997, Task_hours!$E$4:$E$997, AX$2, Task_hours!$G$4:$G$997, $A9) -> 0
A10: Francesco | B10: =SUMIFS(Tasks!$H$3:$H1004, Tasks!$F$3:$F1004, $A10, Tasks!$B$3:$B1004, $A$1, Tasks!$K$3:$K1004, "Backlog") -> 0 | C10: =SUMIFS(Tasks!$H$3:$H1004, Tasks!$G$3:$G1004, $A10, Tasks!$B$3:$B1004, $A$1, Tasks!$K$3:$K1004, "Backlog") -> 0 | D10: =SUMIFS(Tasks!$H$3:$H1004, Tasks!$F$3:$F1004, $A10, Tasks!$B$3:$B1004, $A$1, Tasks!$K$3:$K1004, "Progress")-SUMIFS(Tasks!$I$3:$I1004, Tasks!$F$3:$F1004, $A10, Tasks!$B$3:$B1004, $A$1, Tasks!$K$3:$K1004, "Progress") -> 0 | E10: =SUMIFS(Tasks!$H$3:$H1004, Tasks!$G$3:$G1004, $A10, Tasks!$B$3:$B1004, $A$1, Tasks!$K$3:$K1004, "Progress")-SUMIFS(Tasks!$I$3:$I1004, Tasks!$G$3:$G1004, $A10, Tasks!$B$3:$B1004, $A$1, Tasks!$K$3:$K1004, "Progress") -> 0 | F10: =H10+B10 -> 16.5 | G10: =I10+C10 -> 13 | H10: =SUM(J10,L10,N10,P10,R10,T10,V10,X10,Z10,AB10,AD10,AF10,AH10,AJ10) -> 16.5 | I10: =SUM(K10,M10,O10,Q10,S10,U10,W10,Y10,AA10,AC10,AE10,AG10,AI10,AK10) -> 13 | J10: =SUMIFS(Task_hours!$H$4:$H$997, Task_hours!$E$4:$E$997, J$2, Task_hours!$F$4:$F$997, $A10) -> 0 | K10: =SUMIFS(Task_hours!$H$4:$H$997, Task_hours!$E$4:$E$997, J$2, Task_hours!$G$4:$G$997, $A10) -> 0 | L10: =SUMIFS(Task_hours!$H$4:$H$997, Task_hours!$E$4:$E$997, L$2, Task_hours!$F$4:$F$997, $A10) -> 0 | M10: =SUMIFS(Task_hours!$H$4:$H$997, Task_hours!$E$4:$E$997, L$2, Task_hours!$G$4:$G$997, $A10) -> 0 | N10: =SUMIFS(Task_hours!$H$4:$H$997, Task_hours!$E$4:$E$997, N$2, Task_hours!$F$4:$F$997, $A10) -> 0 | O10: =SUMIFS(Task_hours!$H$4:$H$997, Task_hours!$E$4:$E$997, N$2, Task_hours!$G$4:$G$997, $A10) -> 0 | P10: =SUMIFS(Task_hours!$H$4:$H$997, Task_hours!$E$4:$E$997, P$2, Task_hours!$F$4:$F$997, $A10) -> 2.5 | Q10: =SUMIFS(Task_hours!$H$4:$H$997, Task_hours!$E$4:$E$997, P$2, Task_hours!$G$4:$G$997, $A10) -> 0 | R10: =SUMIFS(Task_hours!$H$4:$H$997, Task_hours!$E$4:$E$997, R$2, Task_hours!$F$4:$F$997, $A10) -> 0 | S10: =SUMIFS(Task_hours!$H$4:$H$997, Task_hours!$E$4:$E$997, R$2, Task_hours!$G$4:$G$997, $A10) -> 0 | T10: =SUMIFS(Task_hours!$H$4:$H$997, Task_hours!$E$4:$E$997, T$2, Task_hours!$F$4:$F$997, $A10) -> 0 | U10: =SUMIFS(Task_hours!$H$4:$H$997, Task_hours!$E$4:$E$997, T$2, Task_hours!$G$4:$G$997, $A10) -> 6 | V10: =SUMIFS(Task_hours!$H$4:$H$997, Task_hours!$E$4:$E$997, V$2, Task_hours!$F$4:$F$997, $A10) -> 0 | W10: =SUMIFS(Task_hours!$H$4:$H$997, Task_hours!$E$4:$E$997, V$2, Task_hours!$G$4:$G$997, $A10) -> 4 | X10: =SUMIFS(Task_hours!$H$4:$H$997, Task_hours!$E$4:$E$997, X$2, Task_hours!$F$4:$F$997, $A10) -> 2.5 | Y10: =SUMIFS(Task_hours!$H$4:$H$997, Task_hours!$E$4:$E$997, X$2, Task_hours!$G$4:$G$997, $A10) -> 0 | Z10: =SUMIFS(Task_hours!$H$4:$H$997, Task_hours!$E$4:$E$997, Z$2, Task_hours!$F$4:$F$997, $A10) -> 1.5 | AA10: =SUMIFS(Task_hours!$H$4:$H$997, Task_hours!$E$4:$E$997, Z$2, Task_hours!$G$4:$G$997, $A10) -> 0 | AB10: =SUMIFS(Task_hours!$H$4:$H$997, Task_hours!$E$4:$E$997, AB$2, Task_hours!$F$4:$F$997, $A10) -> 0 | AC10: =SUMIFS(Task_hours!$H$4:$H$997, Task_hours!$E$4:$E$997, AB$2, Task_hours!$G$4:$G$997, $A10) -> 0 | AD10: =SUMIFS(Task_hours!$H$4:$H$997, Task_hours!$E$4:$E$997, AD$2, Task_hours!$F$4:$F$997, $A10) -> 0 | AE10: =SUMIFS(Task_hours!$H$4:$H$997, Task_hours!$E$4:$E$997, AD$2, Task_hours!$G$4:$G$997, $A10) -> 0 | AF10: =SUMIFS(Task_hours!$H$4:$H$997, Task_hours!$E$4:$E$997, AF$2, Task_hours!$F$4:$F$997, $A10) -> 0 | AG10: =SUMIFS(Task_hours!$H$4:$H$997, Task_hours!$E$4:$E$997, AF$2, Task_hours!$G$4:$G$997, $A10) -> 0 | AH10: =SUMIFS(Task_hours!$H$4:$H$997, Task_hours!$E$4:$E$997, AH$2, Task_hours!$F$4:$F$997, $A10) -> 0 | AI10: =SUMIFS(Task_hours!$H$4:$H$997, Task_hours!$E$4:$E$997, AH$2, Task_hours!$G$4:$G$997, $A10) -> 0 | AJ10: =SUMIFS(Task_hours!$H$4:$H$997, Task_hours!$E$4:$E$997, AJ$2, Task_hours!$F$4:$F$997, $A10) -> 10 | AK10: =SUMIFS(Task_hours!$H$4:$H$997, Task_hours!$E$4:$E$997, AJ$2, Task_hours!$G$4:$G$997, $A10) -> 3 | AL10: =SUMIFS(Task_hours!$H$4:$H$997, Task_hours!$E$4:$E$997, AL$2, Task_hours!$F$4:$F$997, $A10) -> 0 | AM10: =SUMIFS(Task_hours!$H$4:$H$997, Task_hours!$E$4:$E$997, AL$2, Task_hours!$G$4:$G$997, $A10) -> 0 | AN10: =SUMIFS(Task_hours!$H$4:$H$997, Task_hours!$E$4:$E$997, AN$2, Task_hours!$F$4:$F$997, $A10) -> 0 | AO10: =SUMIFS(Task_hours!$H$4:$H$997, Task_hours!$E$4:$E$997, AN$2, Task_hours!$G$4:$G$997, $A10) -> 0 | AP10: =SUMIFS(Task_hours!$H$4:$H$997, Task_hours!$E$4:$E$997, AP$2, Task_hours!$F$4:$F$997, $A10) -> 0 | AQ10: =SUMIFS(Task_hours!$H$4:$H$997, Task_hours!$E$4:$E$997, AP$2, Task_hours!$G$4:$G$997, $A10) -> 0 | AR10: =SUMIFS(Task_hours!$H$4:$H$997, Task_hours!$E$4:$E$997, AR$2, Task_hours!$F$4:$F$997, $A10) -> 0 | AS10: =SUMIFS(Task_hours!$H$4:$H$997, Task_hours!$E$4:$E$997, AR$2, Task_hours!$G$4:$G$997, $A10) -> 0 | AT10: =SUMIFS(Task_hours!$H$4:$H$997, Task_hours!$E$4:$E$997, AT$2, Task_hours!$F$4:$F$997, $A10) -> 0 | AU10: =SUMIFS(Task_hours!$H$4:$H$997, Task_hours!$E$4:$E$997, AT$2, Task_hours!$G$4:$G$997, $A10) -> 0 | AV10: =SUMIFS(Task_hours!$H$4:$H$997, Task_hours!$E$4:$E$997, AV$2, Task_hours!$F$4:$F$997, $A10) -> 0 | AW10: =SUMIFS(Task_hours!$H$4:$H$997, Task_hours!$E$4:$E$997, AV$2, Task_hours!$G$4:$G$997, $A10) -> 0 | AX10: =SUMIFS(Task_hours!$H$4:$H$997, Task_hours!$E$4:$E$997, AX$2, Task_hours!$F$4:$F$997, $A10) -> 0 | AY10: =SUMIFS(Task_hours!$H$4:$H$997, Task_hours!$E$4:$E$997, AX$2, Task_hours!$G$4:$G$997, $A10) -> 0
